Workbook

Sheet 清洗后的数据
A1: 受访者ID | B1: 年级 | C1: 专业类别 | D1: 性别 | E1: AI使用频率 | F1: 每周AI使用时长（小时） | G1: 常用AI工具（多选） | H1: 最常使用场景 | I1: AI提升学习效率评分（1-5） | J1: AI回答准确性评分（1-5） | K1: 担心形成依赖程度（1-5） | L1: 未来继续使用意愿（1-5） | M1: 当前最大痛点 | N1: 最希望增加的功能 | O1: 愿意为AI学习服务付费 | P1: 开放建议 | Q1: 数据质量标记
A2: R001 | B2: 大三 | C2: 人文社科类 | D2: 女 | E2: 几乎每天 | F2: 6.8 | G2: 豆包；Claude；Gemini | H2: 写作/润色 | I2: 4 | J2: 3 | K2: 2 | L2: 4 | M2: 工具太多，不知道怎么选 | N2: 写作与润色助手 | O2: 6-10元/月 | P2: 如果能把不同AI工具整合到一个入口会方便很多。
A3: R002 | B3: 大二 | C3: 人文社科类 | D3: 男 | E3: 每周3-5次 | F3: 6.3 | G3: DeepSeek；Kimi | H3: 编程/调试 | I3: 2 | J3: 3 | K3: 2 | L3: 4 | M3: 工具太多，不知道怎么选 | N3: 写作与润色助手 | O3: 不愿付费 | P3: 如果能把不同AI工具整合到一个入口会方便很多。
A4: R003 | B4: 大四 | C4: 理工类 | D4: 女 | E4: 每周1-2次 | F4: 2.3 | G4: Gemini；DeepSeek | H4: 资料检索 | I4: 3 | J4: 3 | K4: 3 | L4: 4 | M4: 容易产生依赖 | N4: AI工具选择推荐 | O4: 6-10元/月 | P4: 主要担心AI一本正经地给出错误答案。
A5: R004 | B5: 大二 | C5: 理工类 | D5: 男 | E5: 每周3-5次 | F5: 6 | G5: DeepSeek；Gemini；通义千问 | H5: 编程/调试 | I5: 4 | J5: 3 | K5: 4 | L5: 3 | M5: 容易产生依赖 | N5: 代码学习与调试 | O5: 5元/月以内 | P5: 学校课程如果能教怎么正确使用AI会更好。
A6: R005 | B6: 大一 | C6: 医学类 | D6: 女 | E6: 每周1-2次 | F6: 2 | G6: Gemini；Claude | H6: 头脑风暴/方案生成 | I6: 4 | J6: 4 | K6: 3 | L6: 3 | M6: 工具太多，不知道怎么选 | N6: 提示词模板与指导 | O6: 不愿付费 | P6: 主要担心AI一本正经地给出错误答案。
A7: R006 | B7: 大三 | C7: 艺术设计类 | D7: 男 | E7: 每周1-2次 | F7: 1.2 | G7: Claude；DeepSeek；文心一言 | H7: 写作/润色 | I7: 4 | J7: 3 | K7: 3 | L7: 2 | M7: 内容同质化/缺少个性 | N7: 写作与润色助手 | O7: 5元/月以内
A8: R007 | B8: 大四 | C8: 艺术设计类 | D8: 男 | E8: 每周1-2次 | F8: 2.2 | G8: Kimi；Claude | H8: 头脑风暴/方案生成 | I8: 3 | J8: 3 | K8: 4 | L8: 4 | M8: 不知道怎么提问 | N8: 课程资料智能问答 | O8: 6-10元/月 | P8: 主要担心AI一本正经地给出错误答案。
A9: R008 | B9: 大一 | C9: 人文社科类 | D9: 女 | E9: 每周1-2次 | F9: 3.4 | G9: 豆包；DeepSeek | H9: 写作/润色 | I9: 4 | J9: 4 | K9: 3 | L9: 3 | M9: 回答不够准确 | N9: 代码学习与调试 | O9: 5元/月以内 | P9: 希望回答时能直接给出处和原文链接。
A10: R009 | B10: 大一 | C10: 人文社科类 | D10: 不愿透露 | E10: 每周3-5次 | F10: 5.6 | G10: Kimi；豆包 | H10: 写作/润色 | I10: 4 | J10: 2 | K10: 4 | L10: 5 | M10: 不知道怎么提问 | N10: 提示词模板与指导 | O10: 5元/月以内
A11: R010 | B11: 大三 | C11: 人文社科类 | D11: 男 | E11: 几乎每天 | F11: 10.8 | G11: Claude；Gemini；通义千问；文心一言 | H11: 写作/润色 | I11: 4 | J11: 4 | K11: 4 | L11: 4 | M11: 回答不够准确 | N11: 写作与润色助手 | O11: 不愿付费 | P11: 希望回答时能直接给出处和原文链接。
A12: R011 | B12: 大四 | C12: 理工类 | D12: 女 | E12: 每周1-2次 | F12: 1.8 | G12: Kimi；通义千问 | H12: 编程/调试 | I12: 4 | J12: 2 | K12: 4 | L12: 2 | M12: 回答不够准确 | N12: 写作与润色助手 | O12: 不愿付费
A13: R012 | B13: 大一 | C13: 人文社科类 | D13: 女 | E13: 几乎每天 | F13: 5.3 | G13: Claude；豆包 | H13: 写作/润色 | I13: 5 | J13: 3 | K13: 5 | L13: 5 | M13: 不知道怎么提问 | N13: 可靠来源/引用核验 | O13: 5元/月以内
A14: R013 | B14: 大二 | C14: 经管类 | D14: 女 | E14: 每周3-5次 | F14: 5.4 | G14: Kimi；Claude | H14: 资料检索 | I14: 4 | J14: 3 | K14: 4 | L14: 4 | M14: 不知道怎么提问 | N14: 提示词模板与指导 | O14: 20元/月以上 | P14: 如果能针对课程资料回答会更实用。
A15: R014 | B15: 大三 | C15: 人文社科类 | D15: 女 | E15: 几乎每天 | F15: 11.3 | G15: 通义千问；Gemini；Kimi | H15: 资料检索 | I15: 4 | J15: 4 | K15: 4 | L15: 4 | M15: 隐私与数据安全担忧 | N15: 提示词模板与指导 | O15: 11-20元/月 | P15: 希望回答时能直接给出处和原文链接。
A16: R015 | B16: 大三 | C16: 医学类 | D16: 女 | E16: 几乎不用 | F16: 0.4 | G16: Claude | H16: 资料检索 | I16: 3 | J16: 3 | K16: 3 | L16: 2 | M16: 回答不够准确 | N16: 提示词模板与指导 | O16: 11-20元/月 | P16: 希望能根据我的错题和笔记做复习计划。
A17: R016 | B17: 大二 | C17: 医学类 | D17: 女 | E17: 每周3-5次 | F17: 2.9 | G17: ChatGPT；Gemini；豆包 | H17: 资料检索 | I17: 4 | J17: 4 | K17: 3 | L17: 3 | M17: 不知道怎么提问 | N17: 提示词模板与指导 | O17: 20元/月以上 | P17: 希望能根据我的错题和笔记做复习计划。
A18: R017 | B18: 大一 | C18: 理工类 | D18: 女 | E18: 几乎不用 | F18: 0 | G18: 未固定使用 | H18: 作业答疑 | I18: 2 | J18: 3 | K18: 2 | L18: 1 | M18: 回答不够准确 | N18: 写作与润色助手 | O18: 5元/月以内
A19: R018 | B19: 大一 | C19: 人文社科类 | D19: 男 | E19: 每月1-3次 | F19: 1.3 | G19: Gemini | H19: 资料检索 | I19: 3 | J19: 2 | K19: 4 | L19: 2 | M19: 工具太多，不知道怎么选 | N19: 提示词模板与指导 | O19: 5元/月以内
A20: R019 | B20: 大二 | C20: 医学类 | D20: 男 | E20: 每月1-3次 | F20: 1.1 | G20: DeepSeek | H20: 翻译 | I20: 2 | J20: 2 | K20: 2 | L20: 3 | M20: 不知道怎么提问 | N20: 提示词模板与指导 | O20: 不愿付费
A21: R020 | B21: 大四 | C21: 经管类 | D21: 女 | E21: 几乎每天 | F21: 11.9 | G21: DeepSeek；文心一言；ChatGPT | H21: 写作/润色 | I21: 4 | J21: 2 | K21: 5 | L21: 4 | M21: 隐私与数据安全担忧 | N21: 写作与润色助手 | O21: 6-10元/月 | P21: 希望回答时能直接给出处和原文链接。
A22: R021 | B22: 大二 | C22: 医学类 | D22: 女 | E22: 每周3-5次 | F22: 4.5 | G22: 通义千问；Claude；DeepSeek；Gemini | H22: 头脑风暴/方案生成 | I22: 3 | J22: 4 | K22: 3 | L22: 4 | M22: 不知道怎么提问 | N22: 提示词模板与指导 | O22: 5元/月以内 | P22: 学校课程如果能教怎么正确使用AI会更好。
A23: R022 | B23: 大一 | C23: 艺术设计类 | D23: 男 | E23: 几乎不用 | F23: 0.6 | G23: Gemini | H23: 资料检索 | I23: 3 | J23: 3 | K23: 3 | L23: 2 | M23: 隐私与数据安全担忧 | N23: 课程资料智能问答 | O23: 6-10元/月 | P23: 如果能把不同AI工具整合到一个入口会方便很多。
A24: R023 | B24: 大三 | C24: 理工类 | D24: 女 | E24: 几乎每天 | F24: 9.2 | G24: ChatGPT；Claude；豆包 | H24: 写作/润色 | I24: 4 | J24: 3 | K24: 2 | L24: 4 | M24: 内容同质化/缺少个性 | N24: 提示词模板与指导 | O24: 5元/月以内
A25: R024 | B25: 大二 | C25: 理工类 | D25: 男 | E25: 每周3-5次 | F25: 5.9 | G25: ChatGPT；Gemini | H25: 作业答疑 | I25: 4 | J25: 4 | K25: 3 | L25: 4 | M25: 不知道怎么提问 | N25: AI工具选择推荐 | O25: 11-20元/月 | P25: 主要担心AI一本正经地给出错误答案。
A26: R025 | B26: 大二 | C26: 艺术设计类 | D26: 男 | E26: 每周3-5次 | F26: 6.5 | G26: DeepSeek；通义千问 | H26: 写作/润色 | I26: 3 | J26: 3 | K26: 4 | L26: 5 | M26: 隐私与数据安全担忧 | N26: 提示词模板与指导 | O26: 6-10元/月 | P26: 希望能根据我的错题和笔记做复习计划。
A27: R026 | B27: 大二 | C27: 医学类 | D27: 男 | E27: 每月1-3次 | F27: 1 | G27: DeepSeek；文心一言 | H27: 写作/润色 | I27: 3 | J27: 5 | K27: 3 | L27: 2 | M27: 工具太多，不知道怎么选 | N27: 错题/知识点总结 | O27: 不愿付费 | P27: 主要担心AI一本正经地给出错误答案。
A28: R027 | B28: 大三 | C28: 经管类 | D28: 女 | E28: 几乎每天 | F28: 11.3 | G28: ChatGPT；文心一言；通义千问 | H28: 写作/润色 | I28: 4 | J28: 4 | K28: 4 | L28: 4 | M28: 容易产生依赖 | N28: 可靠来源/引用核验 | O28: 6-10元/月 | P28: 写作很方便，但不希望最后大家的内容都差不多。
A29: R028 | B29: 大一 | C29: 理工类 | D29: 女 | E29: 几乎每天 | F29: 9.6 | G29: ChatGPT；通义千问；Gemini；Kimi | H29: 编程/调试 | I29: 5 | J29: 3 | K29: 4 | L29: 4 | M29: 容易产生依赖 | N29: 课程资料智能问答 | O29: 11-20元/月 | P29: 学校课程如果能教怎么正确使用AI会更好。
A30: R029 | B30: 大三 | C30: 经管类 | D30: 女 | E30: 每周1-2次 | F30: 1.4 | G30: Gemini；Claude | H30: 作业答疑 | I30: 3 | J30: 2 | K30: 4 | L30: 4 | M30: 不知道怎么提问 | N30: 提示词模板与指导 | O30: 5元/月以内
A31: R030 | B31: 大二 | C31: 人文社科类 | D31: 女 | E31: 几乎不用 | F31: 0.2 | G31: 未固定使用 | H31: 作业答疑 | I31: 3 | J31: 2 | K31: 3 | L31: 2 | M31: 不知道怎么提问 | N31: 代码学习与调试 | O31: 不愿付费 | P31: 主要担心AI一本正经地给出错误答案。
A32: R031 | B32: 大三 | C32: 经管类 | D32: 男 | E32: 每周3-5次 | F32: 4.1 | G32: 通义千问；豆包 | H32: 资料检索 | I32: 4 | J32: 4 | K32: 3 | L32: 4 | M32: 不知道怎么提问 | N32: AI工具选择推荐 | O32: 不愿付费
A33: R032 | B33: 大二 | C33: 经管类 | D33: 女 | E33: 每周3-5次 | F33: 4 | G33: Claude；DeepSeek | H33: 资料检索 | I33: 3 | J33: 4 | K33: 3 | L33: 3 | M33: 隐私与数据安全担忧 | N33: 可靠来源/引用核验 | O33: 6-10元/月
A34: R033 | B34: 大三 | C34: 艺术设计类 | D34: 女 | E34: 每周1-2次 | F34: 3.4 | G34: ChatGPT | H34: 翻译 | I34: 2 | J34: 3 | K34: 3 | L34: 4 | M34: 不知道怎么提问 | N34: 错题/知识点总结 | O34: 5元/月以内
A35: R034 | B35: 大三 | C35: 理工类 | D35: 女 | E35: 每周3-5次 | F35: 3.9 | G35: 豆包；文心一言 | H35: 编程/调试 | I35: 4 | J35: 2 | K35: 3 | L35: 3 | M35: 容易产生依赖 | N35: 写作与润色助手 | O35: 5元/月以内 | P35: 有时候不知道怎么写提示词，结果质量差异很大。
A36: R035 | B36: 大三 | C36: 理工类 | D36: 女 | E36: 几乎每天 | F36: 8.2 | G36: 豆包；Claude | H36: 头脑风暴/方案生成 | I36: 5 | J36: 4 | K36: 3 | L36: 4 | M36: 不知道怎么提问 | N36: 课程资料智能问答 | O36: 6-10元/月
A37: R036 | B37: 大一 | C37: 经管类 | D37: 女 | E37: 每周1-2次 | F37: 1.2 | G37: 通义千问；Kimi | H37: 写作/润色 | I37: 3 | J37: 2 | K37: 3 | L37: 4 | M37: 不知道怎么提问 | N37: 提示词模板与指导 | O37: 20元/月以上 | P37: 有时候不知道怎么写提示词，结果质量差异很大。
A38: R037 | B38: 大二 | C38: 经管类 | D38: 女 | E38: 每周3-5次 | F38: 5.9 | G38: Kimi；Claude；豆包；Gemini | H38: 头脑风暴/方案生成 | I38: 4 | J38: 3 | K38: 3 | L38: 5 | M38: 隐私与数据安全担忧 | N38: 提示词模板与指导 | O38: 不愿付费
A39: R038 | B39: 大二 | C39: 艺术设计类 | D39: 女 | E39: 每月1-3次 | F39: 0.8 | G39: Gemini；Claude | H39: 头脑风暴/方案生成 | I39: 2 | J39: 1 | K39: 2 | L39: 3 | M39: 不知道怎么提问 | N39: 错题/知识点总结 | O39: 5元/月以内 | P39: 写作很方便，但不希望最后大家的内容都差不多。
A40: R039 | B40: 大二 | C40: 人文社科类 | D40: 男 | E40: 每周3-5次 | F40: 5.7 | G40: Claude；Gemini；DeepSeek；ChatGPT | H40: 头脑风暴/方案生成 | I40: 5 | J40: 5 | K40: 3 | L40: 4 | M40: 回答不够准确 | N40: 错题/知识点总结 | O40: 20元/月以上 | P40: 主要担心AI一本正经地给出错误答案。
...

Sheet 数据清洗说明
A1: 问题类型 | B1: 问题位置 | C1: 原始情况 | D1: 如何处理 | E1: 影响数量 | F1: 是否需要人工确认
A2: 重复数据 | B2: 原始数据第111行（R019） | C2: 与另一条记录各字段一致，仅开放建议单元格的底层空值存储方式不同 | D2: 删除重复记录，保留首次出现记录 | E2: 1 | F2: 否
A3: 无效或低质量数据 | B3: 原始数据第110行（R109） | C3: 除受访者ID外，所有题目均填写“无” | D3: 判定为明显无效问卷并删除 | E3: 1 | F3: 否
A4: 缺失数据 | B4: 开放建议列 | C4: 原始数据中空白/缺失 40 条 | D4: 保留空白，不进行填补 | E4: 40 | F4: 否
A5: 格式和类别不统一 | B5: 原始数据第44行（R043）·年级 | C5: '大二 ' | D5: 去除首尾空格：'大二' | E5: 1 | F5: 否
A6: 格式和类别不统一 | B6: 原始数据第107行（R106）·年级 | C6: '大二 ' | D6: 去除首尾空格：'大二' | E6: 1 | F6: 否
A7: 格式和类别不统一 | B7: 原始数据第107行（R106）·常用AI工具（多选） | C7: 'deepseek；Chat GPT' | D7: 统一AI工具名称写法/大小写：'DeepSeek；ChatGPT' | E7: 1 | F7: 否
A8: 缺失数据 | B8: 原始数据第18行（R017）·每周AI使用时长（小时） | C8: 原值缺失 | D8: 按人工确认结果填入 0 | E8: 1 | F8: 否
A9: 无效或低质量数据 | B9: 原始数据第106行（R105） | C9: AI使用频率、当前最大痛点缺失 | D9: 按人工确认结果删除该记录 | E9: 1 | F9: 否
A10: 异常数据 | B10: 原始数据第108行（R107） | C10: 每周AI使用时长=-2.5；四项1-5评分分别为6、0、7、9 | D10: 按人工确认结果删除该记录 | E10: 1 | F10: 否

Sheet 清洗汇总
A1: 原始记录数 | B1: 删除数 | C1: 修改数 | D1: 待确认数 | E1: 最终记录数
A2: 110 | B2: 4 | C2: 3 | D2: 0 | E2: 106
A4: 口径说明
A5: 删除数按删除的记录数统计；修改数按发生明确格式/类别修正的记录数统计；待确认数按需要人工核实的记录数统计。缺失值仅保留并记录，不计入修改数。

Sheet 年级_AI使用频率
A1: 不同年级（人数与组内占比）
A3: 年级 | B3: 几乎不用 | C3: 每月1-3次 | D3: 每周1-2次 | E3: 每周3-5次 | F3: 几乎每天 | G3: 合计 | H3: 样本占比
A4: 大一 | B4: =COUNTIFS(清洗后的数据!$B$2:$B$107,$A4,清洗后的数据!$E$2:$E$107,B$3) -> 3 | C4: =COUNTIFS(清洗后的数据!$B$2:$B$107,$A4,清洗后的数据!$E$2:$E$107,C$3) -> 4 | D4: =COUNTIFS(清洗后的数据!$B$2:$B$107,$A4,清洗后的数据!$E$2:$E$107,D$3) -> 9 | E4: =COUNTIFS(清洗后的数据!$B$2:$B$107,$A4,清洗后的数据!$E$2:$E$107,E$3) -> 8 | F4: =COUNTIFS(清洗后的数据!$B$2:$B$107,$A4,清洗后的数据!$E$2:$E$107,F$3) -> 6 | G4: =SUM(B4:F4) -> 30 | H4: =G4/SUM($G$4:$G$7) -> 0.28301887
A5: 大二 | B5: =COUNTIFS(清洗后的数据!$B$2:$B$107,$A5,清洗后的数据!$E$2:$E$107,B$3) -> 3 | C5: =COUNTIFS(清洗后的数据!$B$2:$B$107,$A5,清洗后的数据!$E$2:$E$107,C$3) -> 5 | D5: =COUNTIFS(清洗后的数据!$B$2:$B$107,$A5,清洗后的数据!$E$2:$E$107,D$3) -> 5 | E5: =COUNTIFS(清洗后的数据!$B$2:$B$107,$A5,清洗后的数据!$E$2:$E$107,E$3) -> 21 | F5: =COUNTIFS(清洗后的数据!$B$2:$B$107,$A5,清洗后的数据!$E$2:$E$107,F$3) -> 4 | G5: =SUM(B5:F5) -> 38 | H5: =G5/SUM($G$4:$G$7) -> 0.35849057
A6: 大三 | B6: =COUNTIFS(清洗后的数据!$B$2:$B$107,$A6,清洗后的数据!$E$2:$E$107,B$3) -> 2 | C6: =COUNTIFS(清洗后的数据!$B$2:$B$107,$A6,清洗后的数据!$E$2:$E$107,C$3) -> 0 | D6: =COUNTIFS(清洗后的数据!$B$2:$B$107,$A6,清洗后的数据!$E$2:$E$107,D$3) -> 5 | E6: =COUNTIFS(清洗后的数据!$B$2:$B$107,$A6,清洗后的数据!$E$2:$E$107,E$3) -> 8 | F6: =COUNTIFS(清洗后的数据!$B$2:$B$107,$A6,清洗后的数据!$E$2:$E$107,F$3) -> 11 | G6: =SUM(B6:F6) -> 26 | H6: =G6/SUM($G$4:$G$7) -> 0.24528302
A7: 大四 | B7: =COUNTIFS(清洗后的数据!$B$2:$B$107,$A7,清洗后的数据!$E$2:$E$107,B$3) -> 0 | C7: =COUNTIFS(清洗后的数据!$B$2:$B$107,$A7,清洗后的数据!$E$2:$E$107,C$3) -> 2 | D7: =COUNTIFS(清洗后的数据!$B$2:$B$107,$A7,清洗后的数据!$E$2:$E$107,D$3) -> 4 | E7: =COUNTIFS(清洗后的数据!$B$2:$B$107,$A7,清洗后的数据!$E$2:$E$107,E$3) -> 2 | F7: =COUNTIFS(清洗后的数据!$B$2:$B$107,$A7,清洗后的数据!$E$2:$E$107,F$3) -> 4 | G7: =SUM(B7:F7) -> 12 | H7: =G7/SUM($G$4:$G$7) -> 0.11320755
A8: 合计 | B8: =SUM(B4:B7) -> 8 | C8: =SUM(C4:C7) -> 11 | D8: =SUM(D4:D7) -> 23 | E8: =SUM(E4:E7) -> 39 | F8: =SUM(F4:F7) -> 25 | G8: =SUM(G4:G7) -> 106 | H8: =1 -> 1
A12: 年级（组内百分比） | B12: 几乎不用 | C12: 每月1-3次 | D12: 每周1-2次 | E12: 每周3-5次 | F12: 几乎每天 | G12: 合计
A13: 大一 | B13: =B4/$G4 -> 0.1 | C13: =C4/$G4 -> 0.13333333 | D13: =D4/$G4 -> 0.3 | E13: =E4/$G4 -> 0.26666667 | F13: =F4/$G4 -> 0.2 | G13: =SUM(B13:F13) -> 1
A14: 大二 | B14: =B5/$G5 -> 0.078947368 | C14: =C5/$G5 -> 0.13157895 | D14: =D5/$G5 -> 0.13157895 | E14: =E5/$G5 -> 0.55263158 | F14: =F5/$G5 -> 0.10526316 | G14: =SUM(B14:F14) -> 1
A15: 大三 | B15: =B6/$G6 -> 0.076923077 | C15: =C6/$G6 -> 0 | D15: =D6/$G6 -> 0.19230769 | E15: =E6/$G6 -> 0.30769231 | F15: =F6/$G6 -> 0.42307692 | G15: =SUM(B15:F15) -> 1
A16: 大四 | B16: =B7/$G7 -> 0 | C16: =C7/$G7 -> 0.16666667 | D16: =D7/$G7 -> 0.33333333 | E16: =E7/$G7 -> 0.16666667 | F16: =F7/$G7 -> 0.33333333 | G16: =SUM(B16:F16) -> 1
A19: 说明 | B19: 上表为人数；下表为各组内部百分比。右侧采用 100% 堆积条形图，便于比较不同组的 AI 使用频率构成差异。

Sheet 专业_AI使用频率
A1: 不同专业（人数与组内占比）
A3: 专业类别 | B3: 几乎不用 | C3: 每月1-3次 | D3: 每周1-2次 | E3: 每周3-5次 | F3: 几乎每天 | G3: 合计 | H3: 样本占比
A4: 人文社科类 | B4: =COUNTIFS(清洗后的数据!$C$2:$C$107,$A4,清洗后的数据!$E$2:$E$107,B$3) -> 1 | C4: =COUNTIFS(清洗后的数据!$C$2:$C$107,$A4,清洗后的数据!$E$2:$E$107,C$3) -> 3 | D4: =COUNTIFS(清洗后的数据!$C$2:$C$107,$A4,清洗后的数据!$E$2:$E$107,D$3) -> 5 | E4: =COUNTIFS(清洗后的数据!$C$2:$C$107,$A4,清洗后的数据!$E$2:$E$107,E$3) -> 11 | F4: =COUNTIFS(清洗后的数据!$C$2:$C$107,$A4,清洗后的数据!$E$2:$E$107,F$3) -> 7 | G4: =SUM(B4:F4) -> 27 | H4: =G4/SUM($G$4:$G$8) -> 0.25471698
A5: 理工类 | B5: =COUNTIFS(清洗后的数据!$C$2:$C$107,$A5,清洗后的数据!$E$2:$E$107,B$3) -> 3 | C5: =COUNTIFS(清洗后的数据!$C$2:$C$107,$A5,清洗后的数据!$E$2:$E$107,C$3) -> 3 | D5: =COUNTIFS(清洗后的数据!$C$2:$C$107,$A5,清洗后的数据!$E$2:$E$107,D$3) -> 3 | E5: =COUNTIFS(清洗后的数据!$C$2:$C$107,$A5,清洗后的数据!$E$2:$E$107,E$3) -> 5 | F5: =COUNTIFS(清洗后的数据!$C$2:$C$107,$A5,清洗后的数据!$E$2:$E$107,F$3) -> 12 | G5: =SUM(B5:F5) -> 26 | H5: =G5/SUM($G$4:$G$8) -> 0.24528302
A6: 经管类 | B6: =COUNTIFS(清洗后的数据!$C$2:$C$107,$A6,清洗后的数据!$E$2:$E$107,B$3) -> 2 | C6: =COUNTIFS(清洗后的数据!$C$2:$C$107,$A6,清洗后的数据!$E$2:$E$107,C$3) -> 0 | D6: =COUNTIFS(清洗后的数据!$C$2:$C$107,$A6,清洗后的数据!$E$2:$E$107,D$3) -> 7 | E6: =COUNTIFS(清洗后的数据!$C$2:$C$107,$A6,清洗后的数据!$E$2:$E$107,E$3) -> 10 | F6: =COUNTIFS(清洗后的数据!$C$2:$C$107,$A6,清洗后的数据!$E$2:$E$107,F$3) -> 5 | G6: =SUM(B6:F6) -> 24 | H6: =G6/SUM($G$4:$G$8) -> 0.22641509
A7: 医学类 | B7: =COUNTIFS(清洗后的数据!$C$2:$C$107,$A7,清洗后的数据!$E$2:$E$107,B$3) -> 1 | C7: =COUNTIFS(清洗后的数据!$C$2:$C$107,$A7,清洗后的数据!$E$2:$E$107,C$3) -> 2 | D7: =COUNTIFS(清洗后的数据!$C$2:$C$107,$A7,清洗后的数据!$E$2:$E$107,D$3) -> 3 | E7: =COUNTIFS(清洗后的数据!$C$2:$C$107,$A7,清洗后的数据!$E$2:$E$107,E$3) -> 11 | F7: =COUNTIFS(清洗后的数据!$C$2:$C$107,$A7,清洗后的数据!$E$2:$E$107,F$3) -> 0 | G7: =SUM(B7:F7) -> 17 | H7: =G7/SUM($G$4:$G$8) -> 0.16037736
A8: 艺术设计类 | B8: =COUNTIFS(清洗后的数据!$C$2:$C$107,$A8,清洗后的数据!$E$2:$E$107,B$3) -> 1 | C8: =COUNTIFS(清洗后的数据!$C$2:$C$107,$A8,清洗后的数据!$E$2:$E$107,C$3) -> 3 | D8: =COUNTIFS(清洗后的数据!$C$2:$C$107,$A8,清洗后的数据!$E$2:$E$107,D$3) -> 5 | E8: =COUNTIFS(清洗后的数据!$C$2:$C$107,$A8,清洗后的数据!$E$2:$E$107,E$3) -> 2 | F8: =COUNTIFS(清洗后的数据!$C$2:$C$107,$A8,清洗后的数据!$E$2:$E$107,F$3) -> 1 | G8: =SUM(B8:F8) -> 12 | H8: =G8/SUM($G$4:$G$8) -> 0.11320755
A9: 合计 | B9: =SUM(B4:B8) -> 8 | C9: =SUM(C4:C8) -> 11 | D9: =SUM(D4:D8) -> 23 | E9: =SUM(E4:E8) -> 39 | F9: =SUM(F4:F8) -> 25 | G9: =SUM(G4:G8) -> 106 | H9: =1 -> 1
A13: 专业类别（组内百分比） | B13: 几乎不用 | C13: 每月1-3次 | D13: 每周1-2次 | E13: 每周3-5次 | F13: 几乎每天 | G13: 合计
A14: 人文社科类 | B14: =B4/$G4 -> 0.037037037 | C14: =C4/$G4 -> 0.11111111 | D14: =D4/$G4 -> 0.18518519 | E14: =E4/$G4 -> 0.40740741 | F14: =F4/$G4 -> 0.25925926 | G14: =SUM(B14:F14) -> 1
A15: 理工类 | B15: =B5/$G5 -> 0.11538462 | C15: =C5/$G5 -> 0.11538462 | D15: =D5/$G5 -> 0.11538462 | E15: =E5/$G5 -> 0.19230769 | F15: =F5/$G5 -> 0.46153846 | G15: =SUM(B15:F15) -> 1
A16: 经管类 | B16: =B6/$G6 -> 0.083333333 | C16: =C6/$G6 -> 0 | D16: =D6/$G6 -> 0.29166667 | E16: =E6/$G6 -> 0.41666667 | F16: =F6/$G6 -> 0.20833333 | G16: =SUM(B16:F16) -> 1
A17: 医学类 | B17: =B7/$G7 -> 0.058823529 | C17: =C7/$G7 -> 0.11764706 | D17: =D7/$G7 -> 0.17647059 | E17: =E7/$G7 -> 0.64705882 | F17: =F7/$G7 -> 0 | G17: =SUM(B17:F17) -> 1
A18: 艺术设计类 | B18: =B8/$G8 -> 0.083333333 | C18: =C8/$G8 -> 0.25 | D18: =D8/$G8 -> 0.41666667 | E18: =E8/$G8 -> 0.16666667 | F18: =F8/$G8 -> 0.083333333 | G18: =SUM(B18:F18) -> 1
A21: 说明 | B21: 上表为人数；下表为各组内部百分比。右侧采用 100% 堆积条形图，便于比较不同组的 AI 使用频率构成差异。
